Starting dhru as dhuser
/dh/bin/gunicorn_start: line 16: bin/activate: No such file or directory
dirname: missing operand
Try 'dirname --help' for more information.
/dh/bin/gunicorn_start: line 27: exec: gunicorn: not found
Starting dhru as dhuser
/dh/bin/gunicorn_start: line 16: bin/activate: No such file or directory
dirname: missing operand
Try 'dirname --help' for more information.
/dh/bin/gunicorn_start: line 27: exec: gunicorn: not found
Starting dhru as dhuser
/dh/bin/gunicorn_start: line 16: bin/activate: No such file or directory
dirname: missing operand
Try 'dirname --help' for more information.
/dh/bin/gunicorn_start: line 27: exec: gunicorn: not found
Starting dhru as dhuser
/dh/bin/gunicorn_start: line 16: bin/activate: No such file or directory
dirname: missing operand
Try 'dirname --help' for more information.
/dh/bin/gunicorn_start: line 27: exec: gunicorn: not found
Starting dhru as dhuser
/dh/bin/gunicorn_start: line 16: bin/activate: No such file or directory
dirname: missing operand
Try 'dirname --help' for more information.
/dh/bin/gunicorn_start: line 27: exec: gunicorn: not found
Starting dhru as dhuser
/dh/bin/gunicorn_start: line 16: bin/activate: No such file or directory
dirname: missing operand
Try 'dirname --help' for more information.
/dh/bin/gunicorn_start: line 27: exec: gunicorn: not found
Starting dhru as dhuser
/dh/bin/gunicorn_start: line 16: bin/activate: No such file or directory
dirname: missing operand
Try 'dirname --help' for more information.
/dh/bin/gunicorn_start: line 27: exec: gunicorn: not found
Starting dhru as dhuser
/dh/bin/gunicorn_start: line 16: bin/activate: No such file or directory
dirname: missing operand
Try 'dirname --help' for more information.
/dh/bin/gunicorn_start: line 27: exec: gunicorn: not found
Starting dhru as dhuser
/dh/bin/gunicorn_start: line 16: bin/activate: No such file or directory
dirname: missing operand
Try 'dirname --help' for more information.
/dh/bin/gunicorn_start: line 27: exec: gunicorn: not found
Starting dhru as dhuser
/dh/bin/gunicorn_start: line 16: bin/activate: No such file or directory
dirname: missing operand
Try 'dirname --help' for more information.
/dh/bin/gunicorn_start: line 27: exec: gunicorn: not found
Starting dhru as dhuser
/dh/bin/gunicorn_start: line 16: bin/activate: No such file or directory
dirname: missing operand
Try 'dirname --help' for more information.
/dh/bin/gunicorn_start: line 27: exec: gunicorn: not found
Starting dhru as dhuser
/dh/bin/gunicorn_start: line 16: bin/activate: No such file or directory
dirname: missing operand
Try 'dirname --help' for more information.
/dh/bin/gunicorn_start: line 27: exec: gunicorn: not found
Starting dhru as dhuser
/dh/bin/gunicorn_start: line 16: bin/activate: No such file or directory
dirname: missing operand
Try 'dirname --help' for more information.
/dh/bin/gunicorn_start: line 27: /bin/gunicorn: No such file or directory
Starting dhru as dhuser
/dh/bin/gunicorn_start: line 16: bin/activate: No such file or directory
dirname: missing operand
Try 'dirname --help' for more information.
/dh/bin/gunicorn_start: line 27: /bin/gunicorn: No such file or directory
Starting dhru as dhuser
/dh/bin/gunicorn_start: line 16: bin/activate: No such file or directory
dirname: missing operand
Try 'dirname --help' for more information.
/dh/bin/gunicorn_start: line 27: /bin/gunicorn: No such file or directory
Starting dhru as dhuser
/dh/bin/gunicorn_start: line 16: bin/activate: No such file or directory
dirname: missing operand
Try 'dirname --help' for more information.
/dh/bin/gunicorn_start: line 27: /bin/gunicorn: No such file or directory
Starting dhru as dhuser
/dh/bin/gunicorn_start: line 16: bin/activate: No such file or directory
dirname: missing operand
Try 'dirname --help' for more information.
/dh/bin/gunicorn_start: line 27: /bin/gunicorn: No such file or directory
Starting dhru as dhuser
/dh/bin/gunicorn_start: line 16: bin/activate: No such file or directory
dirname: missing operand
Try 'dirname --help' for more information.
/dh/bin/gunicorn_start: line 27: /bin/gunicorn: No such file or directory
Starting dhru as dhuser
/dh/bin/gunicorn_start: line 16: bin/activate: No such file or directory
dirname: missing operand
Try 'dirname --help' for more information.
/dh/bin/gunicorn_start: line 27: /bin/gunicorn: No such file or directory
Starting dhru as dhuser
/dh/bin/gunicorn_start: line 16: bin/activate: No such file or directory
dirname: missing operand
Try 'dirname --help' for more information.
/dh/bin/gunicorn_start: line 27: /bin/gunicorn: No such file or directory
supervisor: couldn't exec /dh/bin/gunicorn_start: ENOEXEC
supervisor: child process was not spawned
supervisor: couldn't exec /dh/bin/gunicorn_start: ENOEXEC
supervisor: child process was not spawned
supervisor: couldn't exec /dh/bin/gunicorn_start: ENOEXEC
supervisor: child process was not spawned
supervisor: couldn't exec /dh/bin/gunicorn_start: ENOEXEC
supervisor: child process was not spawned
Starting dhru as dhuser
In /dh start venv
Now venv Activate
Start Gunicorn
[2017-10-19 17:58:14 +0300] [653] [INFO] Starting gunicorn 19.7.1
[2017-10-19 17:58:14 +0300] [653] [INFO] Listening at: unix:/dh/run/gunicorn.sock (653)
[2017-10-19 17:58:14 +0300] [653] [INFO] Using worker: sync
[2017-10-19 17:58:14 +0300] [660] [INFO] Booting worker with pid: 660
[2017-10-19 17:58:14 +0300] [661] [INFO] Booting worker with pid: 661
[2017-10-19 17:58:14 +0300] [662] [INFO] Booting worker with pid: 662
Starting dhru as dhuser
In /dh start venv
Now venv Activate
Start Gunicorn
[2017-10-29 13:49:19 +0300] [13693] [INFO] Starting gunicorn 19.7.1
[2017-10-29 13:49:19 +0300] [13693] [INFO] Listening at: unix:/dh/run/gunicorn.sock (13693)
[2017-10-29 13:49:19 +0300] [13693] [INFO] Using worker: sync
[2017-10-29 13:49:19 +0300] [13700] [INFO] Booting worker with pid: 13700
[2017-10-29 13:49:19 +0300] [13701] [INFO] Booting worker with pid: 13701
[2017-10-29 13:49:19 +0300] [13702] [INFO] Booting worker with pid: 13702
Starting dhru as dhuser
In /dh start venv
Now venv Activate
Start Gunicorn
[2017-10-29 13:50:35 +0300] [13716] [INFO] Starting gunicorn 19.7.1
[2017-10-29 13:50:35 +0300] [13716] [INFO] Listening at: unix:/dh/run/gunicorn.sock (13716)
[2017-10-29 13:50:35 +0300] [13716] [INFO] Using worker: sync
[2017-10-29 13:50:35 +0300] [13723] [INFO] Booting worker with pid: 13723
[2017-10-29 13:50:35 +0300] [13725] [INFO] Booting worker with pid: 13725
[2017-10-29 13:50:35 +0300] [13726] [INFO] Booting worker with pid: 13726
Starting dhru as dhuser
In /dh start venv
Now venv Activate
Start Gunicorn
[2017-10-29 13:52:01 +0300] [13743] [INFO] Starting gunicorn 19.7.1
[2017-10-29 13:52:01 +0300] [13743] [INFO] Listening at: unix:/dh/run/gunicorn.sock (13743)
[2017-10-29 13:52:01 +0300] [13743] [INFO] Using worker: sync
[2017-10-29 13:52:01 +0300] [13750] [INFO] Booting worker with pid: 13750
[2017-10-29 13:52:01 +0300] [13752] [INFO] Booting worker with pid: 13752
[2017-10-29 13:52:01 +0300] [13753] [INFO] Booting worker with pid: 13753
Starting dhru as dhuser
In /dh start venv
Now venv Activate
Start Gunicorn
[2017-10-29 13:52:56 +0300] [13779] [INFO] Starting gunicorn 19.7.1
[2017-10-29 13:52:56 +0300] [13779] [INFO] Listening at: unix:/dh/run/gunicorn.sock (13779)
[2017-10-29 13:52:56 +0300] [13779] [INFO] Using worker: sync
[2017-10-29 13:52:56 +0300] [13786] [INFO] Booting worker with pid: 13786
[2017-10-29 13:52:56 +0300] [13788] [INFO] Booting worker with pid: 13788
[2017-10-29 13:52:56 +0300] [13789] [INFO] Booting worker with pid: 13789
Starting dhru as dhuser
In /dh start venv
Now venv Activate
Start Gunicorn
[2017-10-30 14:35:48 +0300] [21702] [INFO] Starting gunicorn 19.7.1
[2017-10-30 14:35:48 +0300] [21702] [INFO] Listening at: unix:/dh/run/gunicorn.sock (21702)
[2017-10-30 14:35:48 +0300] [21702] [INFO] Using worker: sync
[2017-10-30 14:35:48 +0300] [21709] [INFO] Booting worker with pid: 21709
[2017-10-30 14:35:48 +0300] [21711] [INFO] Booting worker with pid: 21711
[2017-10-30 14:35:48 +0300] [21712] [INFO] Booting worker with pid: 21712
[2017-10-30 11:35:48 +0000] [21709] [ERROR] Exception in worker process
Traceback (most recent call last):
  File "/dh/lib/python3.6/site-packages/gunicorn/arbiter.py", line 578, in spawn_worker
    worker.init_process()
  File "/dh/lib/python3.6/site-packages/gunicorn/workers/base.py", line 126, in init_process
    self.load_wsgi()
  File "/dh/lib/python3.6/site-packages/gunicorn/workers/base.py", line 135, in load_wsgi
    self.wsgi = self.app.wsgi()
  File "/dh/lib/python3.6/site-packages/gunicorn/app/base.py", line 67, in wsgi
    self.callable = self.load()
  File "/dh/lib/python3.6/site-packages/gunicorn/app/wsgiapp.py", line 65, in load
    return self.load_wsgiapp()
  File "/dh/lib/python3.6/site-packages/gunicorn/app/wsgiapp.py", line 52, in load_wsgiapp
    return util.import_app(self.app_uri)
  File "/dh/lib/python3.6/site-packages/gunicorn/util.py", line 352, in import_app
    __import__(module)
  File "/dh/dhru/wsgi.py", line 16, in <module>
    application = get_wsgi_application()
  File "/dh/lib/python3.6/site-packages/django/core/wsgi.py", line 13, in get_wsgi_application
    django.setup(set_prefix=False)
  File "/dh/lib/python3.6/site-packages/django/__init__.py", line 27, in setup
    apps.populate(settings.INSTALLED_APPS)
  File "/dh/lib/python3.6/site-packages/django/apps/registry.py", line 108, in populate
    app_config.import_models()
  File "/dh/lib/python3.6/site-packages/django/apps/config.py", line 202, in import_models
    self.models_module = import_module(models_module_name)
  File "/dh/lib/python3.6/importlib/__init__.py", line 126, in import_module
    return _bootstrap._gcd_import(name[level:], package, level)
  File "/dh/lib/python3.6/site-packages/social_auth/models.py", line 4, in <module>
    from django.utils.importlib import import_module
ModuleNotFoundError: No module named 'django.utils.importlib'
[2017-10-30 11:35:48 +0000] [21709] [INFO] Worker exiting (pid: 21709)
[2017-10-30 11:35:48 +0000] [21712] [ERROR] Exception in worker process
Traceback (most recent call last):
  File "/dh/lib/python3.6/site-packages/gunicorn/arbiter.py", line 578, in spawn_worker
    worker.init_process()
  File "/dh/lib/python3.6/site-packages/gunicorn/workers/base.py", line 126, in init_process
    self.load_wsgi()
  File "/dh/lib/python3.6/site-packages/gunicorn/workers/base.py", line 135, in load_wsgi
    self.wsgi = self.app.wsgi()
  File "/dh/lib/python3.6/site-packages/gunicorn/app/base.py", line 67, in wsgi
    self.callable = self.load()
  File "/dh/lib/python3.6/site-packages/gunicorn/app/wsgiapp.py", line 65, in load
    return self.load_wsgiapp()
  File "/dh/lib/python3.6/site-packages/gunicorn/app/wsgiapp.py", line 52, in load_wsgiapp
    return util.import_app(self.app_uri)
  File "/dh/lib/python3.6/site-packages/gunicorn/util.py", line 352, in import_app
    __import__(module)
  File "/dh/dhru/wsgi.py", line 16, in <module>
    application = get_wsgi_application()
  File "/dh/lib/python3.6/site-packages/django/core/wsgi.py", line 13, in get_wsgi_application
    django.setup(set_prefix=False)
  File "/dh/lib/python3.6/site-packages/django/__init__.py", line 27, in setup
    apps.populate(settings.INSTALLED_APPS)
  File "/dh/lib/python3.6/site-packages/django/apps/registry.py", line 108, in populate
    app_config.import_models()
  File "/dh/lib/python3.6/site-packages/django/apps/config.py", line 202, in import_models
    self.models_module = import_module(models_module_name)
  File "/dh/lib/python3.6/importlib/__init__.py", line 126, in import_module
    return _bootstrap._gcd_import(name[level:], package, level)
  File "/dh/lib/python3.6/site-packages/social_auth/models.py", line 4, in <module>
    from django.utils.importlib import import_module
ModuleNotFoundError: No module named 'django.utils.importlib'
[2017-10-30 11:35:48 +0000] [21712] [INFO] Worker exiting (pid: 21712)
[2017-10-30 11:35:48 +0000] [21711] [ERROR] Exception in worker process
Traceback (most recent call last):
  File "/dh/lib/python3.6/site-packages/gunicorn/arbiter.py", line 578, in spawn_worker
    worker.init_process()
  File "/dh/lib/python3.6/site-packages/gunicorn/workers/base.py", line 126, in init_process
    self.load_wsgi()
  File "/dh/lib/python3.6/site-packages/gunicorn/workers/base.py", line 135, in load_wsgi
    self.wsgi = self.app.wsgi()
  File "/dh/lib/python3.6/site-packages/gunicorn/app/base.py", line 67, in wsgi
    self.callable = self.load()
  File "/dh/lib/python3.6/site-packages/gunicorn/app/wsgiapp.py", line 65, in load
    return self.load_wsgiapp()
  File "/dh/lib/python3.6/site-packages/gunicorn/app/wsgiapp.py", line 52, in load_wsgiapp
    return util.import_app(self.app_uri)
  File "/dh/lib/python3.6/site-packages/gunicorn/util.py", line 352, in import_app
    __import__(module)
  File "/dh/dhru/wsgi.py", line 16, in <module>
    application = get_wsgi_application()
  File "/dh/lib/python3.6/site-packages/django/core/wsgi.py", line 13, in get_wsgi_application
    django.setup(set_prefix=False)
  File "/dh/lib/python3.6/site-packages/django/__init__.py", line 27, in setup
    apps.populate(settings.INSTALLED_APPS)
  File "/dh/lib/python3.6/site-packages/django/apps/registry.py", line 108, in populate
    app_config.import_models()
  File "/dh/lib/python3.6/site-packages/django/apps/config.py", line 202, in import_models
    self.models_module = import_module(models_module_name)
  File "/dh/lib/python3.6/importlib/__init__.py", line 126, in import_module
    return _bootstrap._gcd_import(name[level:], package, level)
  File "/dh/lib/python3.6/site-packages/social_auth/models.py", line 4, in <module>
    from django.utils.importlib import import_module
ModuleNotFoundError: No module named 'django.utils.importlib'
[2017-10-30 11:35:48 +0000] [21711] [INFO] Worker exiting (pid: 21711)
Traceback (most recent call last):
  File "/dh/lib/python3.6/site-packages/gunicorn/arbiter.py", line 209, in run
    self.sleep()
  File "/dh/lib/python3.6/site-packages/gunicorn/arbiter.py", line 359, in sleep
    ready = select.select([self.PIPE[0]], [], [], 1.0)
  File "/dh/lib/python3.6/site-packages/gunicorn/arbiter.py", line 244, in handle_chld
    self.reap_workers()
  File "/dh/lib/python3.6/site-packages/gunicorn/arbiter.py", line 524, in reap_workers
    raise HaltServer(reason, self.WORKER_BOOT_ERROR)
gunicorn.errors.HaltServer: <HaltServer 'Worker failed to boot.' 3>

During handling of the above exception, another exception occurred:

Traceback (most recent call last):
  File "/dh/bin/gunicorn", line 11, in <module>
    sys.exit(run())
  File "/dh/lib/python3.6/site-packages/gunicorn/app/wsgiapp.py", line 74, in run
    WSGIApplication("%(prog)s [OPTIONS] [APP_MODULE]").run()
  File "/dh/lib/python3.6/site-packages/gunicorn/app/base.py", line 203, in run
    super(Application, self).run()
  File "/dh/lib/python3.6/site-packages/gunicorn/app/base.py", line 72, in run
    Arbiter(self).run()
  File "/dh/lib/python3.6/site-packages/gunicorn/arbiter.py", line 231, in run
    self.halt(reason=inst.reason, exit_status=inst.exit_status)
  File "/dh/lib/python3.6/site-packages/gunicorn/arbiter.py", line 344, in halt
    self.stop()
  File "/dh/lib/python3.6/site-packages/gunicorn/arbiter.py", line 393, in stop
    time.sleep(0.1)
  File "/dh/lib/python3.6/site-packages/gunicorn/arbiter.py", line 244, in handle_chld
    self.reap_workers()
  File "/dh/lib/python3.6/site-packages/gunicorn/arbiter.py", line 524, in reap_workers
    raise HaltServer(reason, self.WORKER_BOOT_ERROR)
gunicorn.errors.HaltServer: <HaltServer 'Worker failed to boot.' 3>
Starting dhru as dhuser
In /dh start venv
Now venv Activate
Start Gunicorn
[2017-10-30 14:35:50 +0300] [21715] [INFO] Starting gunicorn 19.7.1
[2017-10-30 14:35:50 +0300] [21715] [INFO] Listening at: unix:/dh/run/gunicorn.sock (21715)
[2017-10-30 14:35:50 +0300] [21715] [INFO] Using worker: sync
[2017-10-30 14:35:50 +0300] [21722] [INFO] Booting worker with pid: 21722
[2017-10-30 14:35:50 +0300] [21724] [INFO] Booting worker with pid: 21724
[2017-10-30 14:35:50 +0300] [21725] [INFO] Booting worker with pid: 21725
[2017-10-30 11:35:50 +0000] [21722] [ERROR] Exception in worker process
Traceback (most recent call last):
  File "/dh/lib/python3.6/site-packages/gunicorn/arbiter.py", line 578, in spawn_worker
    worker.init_process()
  File "/dh/lib/python3.6/site-packages/gunicorn/workers/base.py", line 126, in init_process
    self.load_wsgi()
  File "/dh/lib/python3.6/site-packages/gunicorn/workers/base.py", line 135, in load_wsgi
    self.wsgi = self.app.wsgi()
  File "/dh/lib/python3.6/site-packages/gunicorn/app/base.py", line 67, in wsgi
    self.callable = self.load()
  File "/dh/lib/python3.6/site-packages/gunicorn/app/wsgiapp.py", line 65, in load
    return self.load_wsgiapp()
  File "/dh/lib/python3.6/site-packages/gunicorn/app/wsgiapp.py", line 52, in load_wsgiapp
    return util.import_app(self.app_uri)
  File "/dh/lib/python3.6/site-packages/gunicorn/util.py", line 352, in import_app
    __import__(module)
  File "/dh/dhru/wsgi.py", line 16, in <module>
    application = get_wsgi_application()
  File "/dh/lib/python3.6/site-packages/django/core/wsgi.py", line 13, in get_wsgi_application
    django.setup(set_prefix=False)
  File "/dh/lib/python3.6/site-packages/django/__init__.py", line 27, in setup
    apps.populate(settings.INSTALLED_APPS)
  File "/dh/lib/python3.6/site-packages/django/apps/registry.py", line 108, in populate
    app_config.import_models()
  File "/dh/lib/python3.6/site-packages/django/apps/config.py", line 202, in import_models
    self.models_module = import_module(models_module_name)
  File "/dh/lib/python3.6/importlib/__init__.py", line 126, in import_module
    return _bootstrap._gcd_import(name[level:], package, level)
  File "/dh/lib/python3.6/site-packages/social_auth/models.py", line 4, in <module>
    from django.utils.importlib import import_module
ModuleNotFoundError: No module named 'django.utils.importlib'
[2017-10-30 11:35:50 +0000] [21722] [INFO] Worker exiting (pid: 21722)
[2017-10-30 11:35:50 +0000] [21724] [ERROR] Exception in worker process
Traceback (most recent call last):
  File "/dh/lib/python3.6/site-packages/gunicorn/arbiter.py", line 578, in spawn_worker
    worker.init_process()
  File "/dh/lib/python3.6/site-packages/gunicorn/workers/base.py", line 126, in init_process
    self.load_wsgi()
  File "/dh/lib/python3.6/site-packages/gunicorn/workers/base.py", line 135, in load_wsgi
    self.wsgi = self.app.wsgi()
  File "/dh/lib/python3.6/site-packages/gunicorn/app/base.py", line 67, in wsgi
    self.callable = self.load()
  File "/dh/lib/python3.6/site-packages/gunicorn/app/wsgiapp.py", line 65, in load
    return self.load_wsgiapp()
  File "/dh/lib/python3.6/site-packages/gunicorn/app/wsgiapp.py", line 52, in load_wsgiapp
    return util.import_app(self.app_uri)
  File "/dh/lib/python3.6/site-packages/gunicorn/util.py", line 352, in import_app
    __import__(module)
  File "/dh/dhru/wsgi.py", line 16, in <module>
    application = get_wsgi_application()
  File "/dh/lib/python3.6/site-packages/django/core/wsgi.py", line 13, in get_wsgi_application
    django.setup(set_prefix=False)
  File "/dh/lib/python3.6/site-packages/django/__init__.py", line 27, in setup
    apps.populate(settings.INSTALLED_APPS)
  File "/dh/lib/python3.6/site-packages/django/apps/registry.py", line 108, in populate
    app_config.import_models()
  File "/dh/lib/python3.6/site-packages/django/apps/config.py", line 202, in import_models
    self.models_module = import_module(models_module_name)
  File "/dh/lib/python3.6/importlib/__init__.py", line 126, in import_module
    return _bootstrap._gcd_import(name[level:], package, level)
  File "/dh/lib/python3.6/site-packages/social_auth/models.py", line 4, in <module>
    from django.utils.importlib import import_module
ModuleNotFoundError: No module named 'django.utils.importlib'
[2017-10-30 11:35:50 +0000] [21724] [INFO] Worker exiting (pid: 21724)
[2017-10-30 11:35:50 +0000] [21725] [ERROR] Exception in worker process
Traceback (most recent call last):
  File "/dh/lib/python3.6/site-packages/gunicorn/arbiter.py", line 578, in spawn_worker
    worker.init_process()
  File "/dh/lib/python3.6/site-packages/gunicorn/workers/base.py", line 126, in init_process
    self.load_wsgi()
  File "/dh/lib/python3.6/site-packages/gunicorn/workers/base.py", line 135, in load_wsgi
    self.wsgi = self.app.wsgi()
  File "/dh/lib/python3.6/site-packages/gunicorn/app/base.py", line 67, in wsgi
    self.callable = self.load()
  File "/dh/lib/python3.6/site-packages/gunicorn/app/wsgiapp.py", line 65, in load
    return self.load_wsgiapp()
  File "/dh/lib/python3.6/site-packages/gunicorn/app/wsgiapp.py", line 52, in load_wsgiapp
    return util.import_app(self.app_uri)
  File "/dh/lib/python3.6/site-packages/gunicorn/util.py", line 352, in import_app
    __import__(module)
  File "/dh/dhru/wsgi.py", line 16, in <module>
    application = get_wsgi_application()
  File "/dh/lib/python3.6/site-packages/django/core/wsgi.py", line 13, in get_wsgi_application
    django.setup(set_prefix=False)
  File "/dh/lib/python3.6/site-packages/django/__init__.py", line 27, in setup
    apps.populate(settings.INSTALLED_APPS)
  File "/dh/lib/python3.6/site-packages/django/apps/registry.py", line 108, in populate
    app_config.import_models()
  File "/dh/lib/python3.6/site-packages/django/apps/config.py", line 202, in import_models
    self.models_module = import_module(models_module_name)
  File "/dh/lib/python3.6/importlib/__init__.py", line 126, in import_module
    return _bootstrap._gcd_import(name[level:], package, level)
  File "/dh/lib/python3.6/site-packages/social_auth/models.py", line 4, in <module>
    from django.utils.importlib import import_module
ModuleNotFoundError: No module named 'django.utils.importlib'
[2017-10-30 11:35:50 +0000] [21725] [INFO] Worker exiting (pid: 21725)
Traceback (most recent call last):
  File "/dh/lib/python3.6/site-packages/gunicorn/arbiter.py", line 209, in run
    self.sleep()
  File "/dh/lib/python3.6/site-packages/gunicorn/arbiter.py", line 359, in sleep
    ready = select.select([self.PIPE[0]], [], [], 1.0)
  File "/dh/lib/python3.6/site-packages/gunicorn/arbiter.py", line 244, in handle_chld
    self.reap_workers()
  File "/dh/lib/python3.6/site-packages/gunicorn/arbiter.py", line 524, in reap_workers
    raise HaltServer(reason, self.WORKER_BOOT_ERROR)
gunicorn.errors.HaltServer: <HaltServer 'Worker failed to boot.' 3>

During handling of the above exception, another exception occurred:

Traceback (most recent call last):
  File "/dh/bin/gunicorn", line 11, in <module>
    sys.exit(run())
  File "/dh/lib/python3.6/site-packages/gunicorn/app/wsgiapp.py", line 74, in run
    WSGIApplication("%(prog)s [OPTIONS] [APP_MODULE]").run()
  File "/dh/lib/python3.6/site-packages/gunicorn/app/base.py", line 203, in run
    super(Application, self).run()
  File "/dh/lib/python3.6/site-packages/gunicorn/app/base.py", line 72, in run
    Arbiter(self).run()
  File "/dh/lib/python3.6/site-packages/gunicorn/arbiter.py", line 231, in run
    self.halt(reason=inst.reason, exit_status=inst.exit_status)
  File "/dh/lib/python3.6/site-packages/gunicorn/arbiter.py", line 344, in halt
    self.stop()
  File "/dh/lib/python3.6/site-packages/gunicorn/arbiter.py", line 393, in stop
    time.sleep(0.1)
  File "/dh/lib/python3.6/site-packages/gunicorn/arbiter.py", line 244, in handle_chld
    self.reap_workers()
  File "/dh/lib/python3.6/site-packages/gunicorn/arbiter.py", line 524, in reap_workers
    raise HaltServer(reason, self.WORKER_BOOT_ERROR)
gunicorn.errors.HaltServer: <HaltServer 'Worker failed to boot.' 3>
Starting dhru as dhuser
In /dh start venv
Now venv Activate
Start Gunicorn
[2017-10-30 14:35:52 +0300] [21728] [INFO] Starting gunicorn 19.7.1
[2017-10-30 14:35:52 +0300] [21728] [INFO] Listening at: unix:/dh/run/gunicorn.sock (21728)
[2017-10-30 14:35:52 +0300] [21728] [INFO] Using worker: sync
[2017-10-30 14:35:52 +0300] [21735] [INFO] Booting worker with pid: 21735
[2017-10-30 14:35:52 +0300] [21737] [INFO] Booting worker with pid: 21737
[2017-10-30 14:35:52 +0300] [21738] [INFO] Booting worker with pid: 21738
[2017-10-30 11:35:53 +0000] [21735] [ERROR] Exception in worker process
Traceback (most recent call last):
  File "/dh/lib/python3.6/site-packages/gunicorn/arbiter.py", line 578, in spawn_worker
    worker.init_process()
  File "/dh/lib/python3.6/site-packages/gunicorn/workers/base.py", line 126, in init_process
    self.load_wsgi()
  File "/dh/lib/python3.6/site-packages/gunicorn/workers/base.py", line 135, in load_wsgi
    self.wsgi = self.app.wsgi()
  File "/dh/lib/python3.6/site-packages/gunicorn/app/base.py", line 67, in wsgi
    self.callable = self.load()
  File "/dh/lib/python3.6/site-packages/gunicorn/app/wsgiapp.py", line 65, in load
    return self.load_wsgiapp()
  File "/dh/lib/python3.6/site-packages/gunicorn/app/wsgiapp.py", line 52, in load_wsgiapp
    return util.import_app(self.app_uri)
  File "/dh/lib/python3.6/site-packages/gunicorn/util.py", line 352, in import_app
    __import__(module)
  File "/dh/dhru/wsgi.py", line 16, in <module>
    application = get_wsgi_application()
  File "/dh/lib/python3.6/site-packages/django/core/wsgi.py", line 13, in get_wsgi_application
    django.setup(set_prefix=False)
  File "/dh/lib/python3.6/site-packages/django/__init__.py", line 27, in setup
    apps.populate(settings.INSTALLED_APPS)
  File "/dh/lib/python3.6/site-packages/django/apps/registry.py", line 108, in populate
    app_config.import_models()
  File "/dh/lib/python3.6/site-packages/django/apps/config.py", line 202, in import_models
    self.models_module = import_module(models_module_name)
  File "/dh/lib/python3.6/importlib/__init__.py", line 126, in import_module
    return _bootstrap._gcd_import(name[level:], package, level)
  File "/dh/lib/python3.6/site-packages/social_auth/models.py", line 4, in <module>
    from django.utils.importlib import import_module
ModuleNotFoundError: No module named 'django.utils.importlib'
[2017-10-30 11:35:53 +0000] [21735] [INFO] Worker exiting (pid: 21735)
[2017-10-30 11:35:53 +0000] [21737] [ERROR] Exception in worker process
Traceback (most recent call last):
  File "/dh/lib/python3.6/site-packages/gunicorn/arbiter.py", line 578, in spawn_worker
    worker.init_process()
  File "/dh/lib/python3.6/site-packages/gunicorn/workers/base.py", line 126, in init_process
    self.load_wsgi()
  File "/dh/lib/python3.6/site-packages/gunicorn/workers/base.py", line 135, in load_wsgi
    self.wsgi = self.app.wsgi()
  File "/dh/lib/python3.6/site-packages/gunicorn/app/base.py", line 67, in wsgi
    self.callable = self.load()
  File "/dh/lib/python3.6/site-packages/gunicorn/app/wsgiapp.py", line 65, in load
    return self.load_wsgiapp()
  File "/dh/lib/python3.6/site-packages/gunicorn/app/wsgiapp.py", line 52, in load_wsgiapp
    return util.import_app(self.app_uri)
  File "/dh/lib/python3.6/site-packages/gunicorn/util.py", line 352, in import_app
    __import__(module)
  File "/dh/dhru/wsgi.py", line 16, in <module>
    application = get_wsgi_application()
  File "/dh/lib/python3.6/site-packages/django/core/wsgi.py", line 13, in get_wsgi_application
    django.setup(set_prefix=False)
  File "/dh/lib/python3.6/site-packages/django/__init__.py", line 27, in setup
    apps.populate(settings.INSTALLED_APPS)
  File "/dh/lib/python3.6/site-packages/django/apps/registry.py", line 108, in populate
    app_config.import_models()
  File "/dh/lib/python3.6/site-packages/django/apps/config.py", line 202, in import_models
    self.models_module = import_module(models_module_name)
  File "/dh/lib/python3.6/importlib/__init__.py", line 126, in import_module
    return _bootstrap._gcd_import(name[level:], package, level)
  File "/dh/lib/python3.6/site-packages/social_auth/models.py", line 4, in <module>
    from django.utils.importlib import import_module
ModuleNotFoundError: No module named 'django.utils.importlib'
[2017-10-30 11:35:53 +0000] [21737] [INFO] Worker exiting (pid: 21737)
[2017-10-30 11:35:53 +0000] [21738] [ERROR] Exception in worker process
Traceback (most recent call last):
  File "/dh/lib/python3.6/site-packages/gunicorn/arbiter.py", line 578, in spawn_worker
    worker.init_process()
  File "/dh/lib/python3.6/site-packages/gunicorn/workers/base.py", line 126, in init_process
    self.load_wsgi()
  File "/dh/lib/python3.6/site-packages/gunicorn/workers/base.py", line 135, in load_wsgi
    self.wsgi = self.app.wsgi()
  File "/dh/lib/python3.6/site-packages/gunicorn/app/base.py", line 67, in wsgi
    self.callable = self.load()
  File "/dh/lib/python3.6/site-packages/gunicorn/app/wsgiapp.py", line 65, in load
    return self.load_wsgiapp()
  File "/dh/lib/python3.6/site-packages/gunicorn/app/wsgiapp.py", line 52, in load_wsgiapp
    return util.import_app(self.app_uri)
  File "/dh/lib/python3.6/site-packages/gunicorn/util.py", line 352, in import_app
    __import__(module)
  File "/dh/dhru/wsgi.py", line 16, in <module>
    application = get_wsgi_application()
  File "/dh/lib/python3.6/site-packages/django/core/wsgi.py", line 13, in get_wsgi_application
    django.setup(set_prefix=False)
  File "/dh/lib/python3.6/site-packages/django/__init__.py", line 27, in setup
    apps.populate(settings.INSTALLED_APPS)
  File "/dh/lib/python3.6/site-packages/django/apps/registry.py", line 108, in populate
    app_config.import_models()
  File "/dh/lib/python3.6/site-packages/django/apps/config.py", line 202, in import_models
    self.models_module = import_module(models_module_name)
  File "/dh/lib/python3.6/importlib/__init__.py", line 126, in import_module
    return _bootstrap._gcd_import(name[level:], package, level)
  File "/dh/lib/python3.6/site-packages/social_auth/models.py", line 4, in <module>
    from django.utils.importlib import import_module
ModuleNotFoundError: No module named 'django.utils.importlib'
[2017-10-30 11:35:53 +0000] [21738] [INFO] Worker exiting (pid: 21738)
Traceback (most recent call last):
  File "/dh/lib/python3.6/site-packages/gunicorn/arbiter.py", line 209, in run
    self.sleep()
  File "/dh/lib/python3.6/site-packages/gunicorn/arbiter.py", line 359, in sleep
    ready = select.select([self.PIPE[0]], [], [], 1.0)
  File "/dh/lib/python3.6/site-packages/gunicorn/arbiter.py", line 244, in handle_chld
    self.reap_workers()
  File "/dh/lib/python3.6/site-packages/gunicorn/arbiter.py", line 524, in reap_workers
    raise HaltServer(reason, self.WORKER_BOOT_ERROR)
gunicorn.errors.HaltServer: <HaltServer 'Worker failed to boot.' 3>

During handling of the above exception, another exception occurred:

Traceback (most recent call last):
  File "/dh/bin/gunicorn", line 11, in <module>
    sys.exit(run())
  File "/dh/lib/python3.6/site-packages/gunicorn/app/wsgiapp.py", line 74, in run
    WSGIApplication("%(prog)s [OPTIONS] [APP_MODULE]").run()
  File "/dh/lib/python3.6/site-packages/gunicorn/app/base.py", line 203, in run
    super(Application, self).run()
  File "/dh/lib/python3.6/site-packages/gunicorn/app/base.py", line 72, in run
    Arbiter(self).run()
  File "/dh/lib/python3.6/site-packages/gunicorn/arbiter.py", line 231, in run
    self.halt(reason=inst.reason, exit_status=inst.exit_status)
  File "/dh/lib/python3.6/site-packages/gunicorn/arbiter.py", line 344, in halt
    self.stop()
  File "/dh/lib/python3.6/site-packages/gunicorn/arbiter.py", line 393, in stop
    time.sleep(0.1)
  File "/dh/lib/python3.6/site-packages/gunicorn/arbiter.py", line 244, in handle_chld
    self.reap_workers()
  File "/dh/lib/python3.6/site-packages/gunicorn/arbiter.py", line 524, in reap_workers
    raise HaltServer(reason, self.WORKER_BOOT_ERROR)
gunicorn.errors.HaltServer: <HaltServer 'Worker failed to boot.' 3>
Starting dhru as dhuser
In /dh start venv
Now venv Activate
Start Gunicorn
[2017-10-30 14:35:56 +0300] [21754] [INFO] Starting gunicorn 19.7.1
[2017-10-30 14:35:56 +0300] [21754] [INFO] Listening at: unix:/dh/run/gunicorn.sock (21754)
[2017-10-30 14:35:56 +0300] [21754] [INFO] Using worker: sync
[2017-10-30 14:35:56 +0300] [21761] [INFO] Booting worker with pid: 21761
[2017-10-30 14:35:56 +0300] [21763] [INFO] Booting worker with pid: 21763
[2017-10-30 14:35:56 +0300] [21764] [INFO] Booting worker with pid: 21764
[2017-10-30 11:35:56 +0000] [21761] [ERROR] Exception in worker process
Traceback (most recent call last):
  File "/dh/lib/python3.6/site-packages/gunicorn/arbiter.py", line 578, in spawn_worker
    worker.init_process()
  File "/dh/lib/python3.6/site-packages/gunicorn/workers/base.py", line 126, in init_process
    self.load_wsgi()
  File "/dh/lib/python3.6/site-packages/gunicorn/workers/base.py", line 135, in load_wsgi
    self.wsgi = self.app.wsgi()
  File "/dh/lib/python3.6/site-packages/gunicorn/app/base.py", line 67, in wsgi
    self.callable = self.load()
  File "/dh/lib/python3.6/site-packages/gunicorn/app/wsgiapp.py", line 65, in load
    return self.load_wsgiapp()
  File "/dh/lib/python3.6/site-packages/gunicorn/app/wsgiapp.py", line 52, in load_wsgiapp
    return util.import_app(self.app_uri)
  File "/dh/lib/python3.6/site-packages/gunicorn/util.py", line 352, in import_app
    __import__(module)
  File "/dh/dhru/wsgi.py", line 16, in <module>
    application = get_wsgi_application()
  File "/dh/lib/python3.6/site-packages/django/core/wsgi.py", line 13, in get_wsgi_application
    django.setup(set_prefix=False)
  File "/dh/lib/python3.6/site-packages/django/__init__.py", line 27, in setup
    apps.populate(settings.INSTALLED_APPS)
  File "/dh/lib/python3.6/site-packages/django/apps/registry.py", line 108, in populate
    app_config.import_models()
  File "/dh/lib/python3.6/site-packages/django/apps/config.py", line 202, in import_models
    self.models_module = import_module(models_module_name)
  File "/dh/lib/python3.6/importlib/__init__.py", line 126, in import_module
    return _bootstrap._gcd_import(name[level:], package, level)
  File "/dh/lib/python3.6/site-packages/social_auth/models.py", line 4, in <module>
    from django.utils.importlib import import_module
ModuleNotFoundError: No module named 'django.utils.importlib'
[2017-10-30 11:35:56 +0000] [21761] [INFO] Worker exiting (pid: 21761)
[2017-10-30 11:35:56 +0000] [21763] [ERROR] Exception in worker process
Traceback (most recent call last):
  File "/dh/lib/python3.6/site-packages/gunicorn/arbiter.py", line 578, in spawn_worker
    worker.init_process()
  File "/dh/lib/python3.6/site-packages/gunicorn/workers/base.py", line 126, in init_process
    self.load_wsgi()
  File "/dh/lib/python3.6/site-packages/gunicorn/workers/base.py", line 135, in load_wsgi
    self.wsgi = self.app.wsgi()
  File "/dh/lib/python3.6/site-packages/gunicorn/app/base.py", line 67, in wsgi
    self.callable = self.load()
  File "/dh/lib/python3.6/site-packages/gunicorn/app/wsgiapp.py", line 65, in load
    return self.load_wsgiapp()
  File "/dh/lib/python3.6/site-packages/gunicorn/app/wsgiapp.py", line 52, in load_wsgiapp
    return util.import_app(self.app_uri)
  File "/dh/lib/python3.6/site-packages/gunicorn/util.py", line 352, in import_app
    __import__(module)
  File "/dh/dhru/wsgi.py", line 16, in <module>
    application = get_wsgi_application()
  File "/dh/lib/python3.6/site-packages/django/core/wsgi.py", line 13, in get_wsgi_application
    django.setup(set_prefix=False)
  File "/dh/lib/python3.6/site-packages/django/__init__.py", line 27, in setup
    apps.populate(settings.INSTALLED_APPS)
  File "/dh/lib/python3.6/site-packages/django/apps/registry.py", line 108, in populate
    app_config.import_models()
  File "/dh/lib/python3.6/site-packages/django/apps/config.py", line 202, in import_models
    self.models_module = import_module(models_module_name)
  File "/dh/lib/python3.6/importlib/__init__.py", line 126, in import_module
    return _bootstrap._gcd_import(name[level:], package, level)
  File "/dh/lib/python3.6/site-packages/social_auth/models.py", line 4, in <module>
    from django.utils.importlib import import_module
ModuleNotFoundError: No module named 'django.utils.importlib'
[2017-10-30 11:35:56 +0000] [21763] [INFO] Worker exiting (pid: 21763)
[2017-10-30 11:35:56 +0000] [21764] [ERROR] Exception in worker process
Traceback (most recent call last):
  File "/dh/lib/python3.6/site-packages/gunicorn/arbiter.py", line 578, in spawn_worker
    worker.init_process()
  File "/dh/lib/python3.6/site-packages/gunicorn/workers/base.py", line 126, in init_process
    self.load_wsgi()
  File "/dh/lib/python3.6/site-packages/gunicorn/workers/base.py", line 135, in load_wsgi
    self.wsgi = self.app.wsgi()
  File "/dh/lib/python3.6/site-packages/gunicorn/app/base.py", line 67, in wsgi
    self.callable = self.load()
  File "/dh/lib/python3.6/site-packages/gunicorn/app/wsgiapp.py", line 65, in load
    return self.load_wsgiapp()
  File "/dh/lib/python3.6/site-packages/gunicorn/app/wsgiapp.py", line 52, in load_wsgiapp
    return util.import_app(self.app_uri)
  File "/dh/lib/python3.6/site-packages/gunicorn/util.py", line 352, in import_app
    __import__(module)
  File "/dh/dhru/wsgi.py", line 16, in <module>
    application = get_wsgi_application()
  File "/dh/lib/python3.6/site-packages/django/core/wsgi.py", line 13, in get_wsgi_application
    django.setup(set_prefix=False)
  File "/dh/lib/python3.6/site-packages/django/__init__.py", line 27, in setup
    apps.populate(settings.INSTALLED_APPS)
  File "/dh/lib/python3.6/site-packages/django/apps/registry.py", line 108, in populate
    app_config.import_models()
  File "/dh/lib/python3.6/site-packages/django/apps/config.py", line 202, in import_models
    self.models_module = import_module(models_module_name)
  File "/dh/lib/python3.6/importlib/__init__.py", line 126, in import_module
    return _bootstrap._gcd_import(name[level:], package, level)
  File "/dh/lib/python3.6/site-packages/social_auth/models.py", line 4, in <module>
    from django.utils.importlib import import_module
ModuleNotFoundError: No module named 'django.utils.importlib'
[2017-10-30 11:35:56 +0000] [21764] [INFO] Worker exiting (pid: 21764)
Traceback (most recent call last):
  File "/dh/lib/python3.6/site-packages/gunicorn/arbiter.py", line 209, in run
    self.sleep()
  File "/dh/lib/python3.6/site-packages/gunicorn/arbiter.py", line 359, in sleep
    ready = select.select([self.PIPE[0]], [], [], 1.0)
  File "/dh/lib/python3.6/site-packages/gunicorn/arbiter.py", line 244, in handle_chld
    self.reap_workers()
  File "/dh/lib/python3.6/site-packages/gunicorn/arbiter.py", line 524, in reap_workers
    raise HaltServer(reason, self.WORKER_BOOT_ERROR)
gunicorn.errors.HaltServer: <HaltServer 'Worker failed to boot.' 3>

During handling of the above exception, another exception occurred:

Traceback (most recent call last):
  File "/dh/bin/gunicorn", line 11, in <module>
    sys.exit(run())
  File "/dh/lib/python3.6/site-packages/gunicorn/app/wsgiapp.py", line 74, in run
    WSGIApplication("%(prog)s [OPTIONS] [APP_MODULE]").run()
  File "/dh/lib/python3.6/site-packages/gunicorn/app/base.py", line 203, in run
    super(Application, self).run()
  File "/dh/lib/python3.6/site-packages/gunicorn/app/base.py", line 72, in run
    Arbiter(self).run()
  File "/dh/lib/python3.6/site-packages/gunicorn/arbiter.py", line 231, in run
    self.halt(reason=inst.reason, exit_status=inst.exit_status)
  File "/dh/lib/python3.6/site-packages/gunicorn/arbiter.py", line 344, in halt
    self.stop()
  File "/dh/lib/python3.6/site-packages/gunicorn/arbiter.py", line 393, in stop
    time.sleep(0.1)
  File "/dh/lib/python3.6/site-packages/gunicorn/arbiter.py", line 244, in handle_chld
    self.reap_workers()
  File "/dh/lib/python3.6/site-packages/gunicorn/arbiter.py", line 524, in reap_workers
    raise HaltServer(reason, self.WORKER_BOOT_ERROR)
gunicorn.errors.HaltServer: <HaltServer 'Worker failed to boot.' 3>
Starting dhru as dhuser
In /dh start venv
Now venv Activate
Start Gunicorn
[2017-10-30 14:38:14 +0300] [676] [INFO] Starting gunicorn 19.7.1
[2017-10-30 14:38:14 +0300] [676] [INFO] Listening at: unix:/dh/run/gunicorn.sock (676)
[2017-10-30 14:38:14 +0300] [676] [INFO] Using worker: sync
[2017-10-30 14:38:14 +0300] [683] [INFO] Booting worker with pid: 683
[2017-10-30 14:38:14 +0300] [684] [INFO] Booting worker with pid: 684
[2017-10-30 14:38:14 +0300] [685] [INFO] Booting worker with pid: 685
[2017-10-30 11:38:18 +0000] [685] [ERROR] Exception in worker process
Traceback (most recent call last):
  File "/dh/lib/python3.6/site-packages/gunicorn/arbiter.py", line 578, in spawn_worker
    worker.init_process()
  File "/dh/lib/python3.6/site-packages/gunicorn/workers/base.py", line 126, in init_process
    self.load_wsgi()
  File "/dh/lib/python3.6/site-packages/gunicorn/workers/base.py", line 135, in load_wsgi
    self.wsgi = self.app.wsgi()
  File "/dh/lib/python3.6/site-packages/gunicorn/app/base.py", line 67, in wsgi
    self.callable = self.load()
  File "/dh/lib/python3.6/site-packages/gunicorn/app/wsgiapp.py", line 65, in load
    return self.load_wsgiapp()
  File "/dh/lib/python3.6/site-packages/gunicorn/app/wsgiapp.py", line 52, in load_wsgiapp
    return util.import_app(self.app_uri)
  File "/dh/lib/python3.6/site-packages/gunicorn/util.py", line 352, in import_app
    __import__(module)
  File "/dh/dhru/wsgi.py", line 16, in <module>
    application = get_wsgi_application()
  File "/dh/lib/python3.6/site-packages/django/core/wsgi.py", line 13, in get_wsgi_application
    django.setup(set_prefix=False)
  File "/dh/lib/python3.6/site-packages/django/__init__.py", line 27, in setup
    apps.populate(settings.INSTALLED_APPS)
  File "/dh/lib/python3.6/site-packages/django/apps/registry.py", line 108, in populate
    app_config.import_models()
  File "/dh/lib/python3.6/site-packages/django/apps/config.py", line 202, in import_models
    self.models_module = import_module(models_module_name)
  File "/dh/lib/python3.6/importlib/__init__.py", line 126, in import_module
    return _bootstrap._gcd_import(name[level:], package, level)
  File "/dh/lib/python3.6/site-packages/social_auth/models.py", line 4, in <module>
    from django.utils.importlib import import_module
ModuleNotFoundError: No module named 'django.utils.importlib'
[2017-10-30 11:38:18 +0000] [684] [ERROR] Exception in worker process
Traceback (most recent call last):
  File "/dh/lib/python3.6/site-packages/gunicorn/arbiter.py", line 578, in spawn_worker
    worker.init_process()
  File "/dh/lib/python3.6/site-packages/gunicorn/workers/base.py", line 126, in init_process
    self.load_wsgi()
  File "/dh/lib/python3.6/site-packages/gunicorn/workers/base.py", line 135, in load_wsgi
    self.wsgi = self.app.wsgi()
  File "/dh/lib/python3.6/site-packages/gunicorn/app/base.py", line 67, in wsgi
    self.callable = self.load()
  File "/dh/lib/python3.6/site-packages/gunicorn/app/wsgiapp.py", line 65, in load
    return self.load_wsgiapp()
  File "/dh/lib/python3.6/site-packages/gunicorn/app/wsgiapp.py", line 52, in load_wsgiapp
    return util.import_app(self.app_uri)
  File "/dh/lib/python3.6/site-packages/gunicorn/util.py", line 352, in import_app
    __import__(module)
  File "/dh/dhru/wsgi.py", line 16, in <module>
    application = get_wsgi_application()
  File "/dh/lib/python3.6/site-packages/django/core/wsgi.py", line 13, in get_wsgi_application
    django.setup(set_prefix=False)
  File "/dh/lib/python3.6/site-packages/django/__init__.py", line 27, in setup
    apps.populate(settings.INSTALLED_APPS)
  File "/dh/lib/python3.6/site-packages/django/apps/registry.py", line 108, in populate
    app_config.import_models()
  File "/dh/lib/python3.6/site-packages/django/apps/config.py", line 202, in import_models
    self.models_module = import_module(models_module_name)
  File "/dh/lib/python3.6/importlib/__init__.py", line 126, in import_module
    return _bootstrap._gcd_import(name[level:], package, level)
  File "/dh/lib/python3.6/site-packages/social_auth/models.py", line 4, in <module>
    from django.utils.importlib import import_module
ModuleNotFoundError: No module named 'django.utils.importlib'
[2017-10-30 11:38:18 +0000] [684] [INFO] Worker exiting (pid: 684)
[2017-10-30 11:38:18 +0000] [683] [ERROR] Exception in worker process
Traceback (most recent call last):
  File "/dh/lib/python3.6/site-packages/gunicorn/arbiter.py", line 578, in spawn_worker
    worker.init_process()
  File "/dh/lib/python3.6/site-packages/gunicorn/workers/base.py", line 126, in init_process
    self.load_wsgi()
  File "/dh/lib/python3.6/site-packages/gunicorn/workers/base.py", line 135, in load_wsgi
    self.wsgi = self.app.wsgi()
  File "/dh/lib/python3.6/site-packages/gunicorn/app/base.py", line 67, in wsgi
    self.callable = self.load()
  File "/dh/lib/python3.6/site-packages/gunicorn/app/wsgiapp.py", line 65, in load
    return self.load_wsgiapp()
  File "/dh/lib/python3.6/site-packages/gunicorn/app/wsgiapp.py", line 52, in load_wsgiapp
    return util.import_app(self.app_uri)
  File "/dh/lib/python3.6/site-packages/gunicorn/util.py", line 352, in import_app
    __import__(module)
  File "/dh/dhru/wsgi.py", line 16, in <module>
    application = get_wsgi_application()
  File "/dh/lib/python3.6/site-packages/django/core/wsgi.py", line 13, in get_wsgi_application
    django.setup(set_prefix=False)
  File "/dh/lib/python3.6/site-packages/django/__init__.py", line 27, in setup
    apps.populate(settings.INSTALLED_APPS)
  File "/dh/lib/python3.6/site-packages/django/apps/registry.py", line 108, in populate
    app_config.import_models()
  File "/dh/lib/python3.6/site-packages/django/apps/config.py", line 202, in import_models
    self.models_module = import_module(models_module_name)
  File "/dh/lib/python3.6/importlib/__init__.py", line 126, in import_module
    return _bootstrap._gcd_import(name[level:], package, level)
  File "/dh/lib/python3.6/site-packages/social_auth/models.py", line 4, in <module>
    from django.utils.importlib import import_module
ModuleNotFoundError: No module named 'django.utils.importlib'
[2017-10-30 11:38:18 +0000] [683] [INFO] Worker exiting (pid: 683)
[2017-10-30 11:38:18 +0000] [685] [INFO] Worker exiting (pid: 685)
[2017-10-30 14:38:19 +0300] [676] [INFO] Shutting down: Master
[2017-10-30 14:38:19 +0300] [676] [INFO] Reason: Worker failed to boot.
Starting dhru as dhuser
In /dh start venv
Now venv Activate
Start Gunicorn
[2017-10-30 14:38:20 +0300] [689] [INFO] Starting gunicorn 19.7.1
[2017-10-30 14:38:20 +0300] [689] [INFO] Listening at: unix:/dh/run/gunicorn.sock (689)
[2017-10-30 14:38:20 +0300] [689] [INFO] Using worker: sync
[2017-10-30 14:38:20 +0300] [696] [INFO] Booting worker with pid: 696
[2017-10-30 14:38:20 +0300] [697] [INFO] Booting worker with pid: 697
[2017-10-30 14:38:20 +0300] [700] [INFO] Booting worker with pid: 700
[2017-10-30 11:38:20 +0000] [696] [ERROR] Exception in worker process
Traceback (most recent call last):
  File "/dh/lib/python3.6/site-packages/gunicorn/arbiter.py", line 578, in spawn_worker
    worker.init_process()
  File "/dh/lib/python3.6/site-packages/gunicorn/workers/base.py", line 126, in init_process
    self.load_wsgi()
  File "/dh/lib/python3.6/site-packages/gunicorn/workers/base.py", line 135, in load_wsgi
    self.wsgi = self.app.wsgi()
  File "/dh/lib/python3.6/site-packages/gunicorn/app/base.py", line 67, in wsgi
    self.callable = self.load()
  File "/dh/lib/python3.6/site-packages/gunicorn/app/wsgiapp.py", line 65, in load
    return self.load_wsgiapp()
  File "/dh/lib/python3.6/site-packages/gunicorn/app/wsgiapp.py", line 52, in load_wsgiapp
    return util.import_app(self.app_uri)
  File "/dh/lib/python3.6/site-packages/gunicorn/util.py", line 352, in import_app
    __import__(module)
  File "/dh/dhru/wsgi.py", line 16, in <module>
    application = get_wsgi_application()
  File "/dh/lib/python3.6/site-packages/django/core/wsgi.py", line 13, in get_wsgi_application
    django.setup(set_prefix=False)
  File "/dh/lib/python3.6/site-packages/django/__init__.py", line 27, in setup
    apps.populate(settings.INSTALLED_APPS)
  File "/dh/lib/python3.6/site-packages/django/apps/registry.py", line 108, in populate
    app_config.import_models()
  File "/dh/lib/python3.6/site-packages/django/apps/config.py", line 202, in import_models
    self.models_module = import_module(models_module_name)
  File "/dh/lib/python3.6/importlib/__init__.py", line 126, in import_module
    return _bootstrap._gcd_import(name[level:], package, level)
  File "/dh/lib/python3.6/site-packages/social_auth/models.py", line 4, in <module>
    from django.utils.importlib import import_module
ModuleNotFoundError: No module named 'django.utils.importlib'
[2017-10-30 11:38:20 +0000] [696] [INFO] Worker exiting (pid: 696)
[2017-10-30 11:38:20 +0000] [697] [ERROR] Exception in worker process
Traceback (most recent call last):
  File "/dh/lib/python3.6/site-packages/gunicorn/arbiter.py", line 578, in spawn_worker
    worker.init_process()
  File "/dh/lib/python3.6/site-packages/gunicorn/workers/base.py", line 126, in init_process
    self.load_wsgi()
  File "/dh/lib/python3.6/site-packages/gunicorn/workers/base.py", line 135, in load_wsgi
    self.wsgi = self.app.wsgi()
  File "/dh/lib/python3.6/site-packages/gunicorn/app/base.py", line 67, in wsgi
    self.callable = self.load()
  File "/dh/lib/python3.6/site-packages/gunicorn/app/wsgiapp.py", line 65, in load
    return self.load_wsgiapp()
  File "/dh/lib/python3.6/site-packages/gunicorn/app/wsgiapp.py", line 52, in load_wsgiapp
    return util.import_app(self.app_uri)
  File "/dh/lib/python3.6/site-packages/gunicorn/util.py", line 352, in import_app
    __import__(module)
  File "/dh/dhru/wsgi.py", line 16, in <module>
    application = get_wsgi_application()
  File "/dh/lib/python3.6/site-packages/django/core/wsgi.py", line 13, in get_wsgi_application
    django.setup(set_prefix=False)
  File "/dh/lib/python3.6/site-packages/django/__init__.py", line 27, in setup
    apps.populate(settings.INSTALLED_APPS)
  File "/dh/lib/python3.6/site-packages/django/apps/registry.py", line 108, in populate
    app_config.import_models()
  File "/dh/lib/python3.6/site-packages/django/apps/config.py", line 202, in import_models
    self.models_module = import_module(models_module_name)
  File "/dh/lib/python3.6/importlib/__init__.py", line 126, in import_module
    return _bootstrap._gcd_import(name[level:], package, level)
  File "/dh/lib/python3.6/site-packages/social_auth/models.py", line 4, in <module>
    from django.utils.importlib import import_module
ModuleNotFoundError: No module named 'django.utils.importlib'
[2017-10-30 11:38:20 +0000] [697] [INFO] Worker exiting (pid: 697)
[2017-10-30 11:38:20 +0000] [700] [ERROR] Exception in worker process
Traceback (most recent call last):
  File "/dh/lib/python3.6/site-packages/gunicorn/arbiter.py", line 578, in spawn_worker
    worker.init_process()
  File "/dh/lib/python3.6/site-packages/gunicorn/workers/base.py", line 126, in init_process
    self.load_wsgi()
  File "/dh/lib/python3.6/site-packages/gunicorn/workers/base.py", line 135, in load_wsgi
    self.wsgi = self.app.wsgi()
  File "/dh/lib/python3.6/site-packages/gunicorn/app/base.py", line 67, in wsgi
    self.callable = self.load()
  File "/dh/lib/python3.6/site-packages/gunicorn/app/wsgiapp.py", line 65, in load
    return self.load_wsgiapp()
  File "/dh/lib/python3.6/site-packages/gunicorn/app/wsgiapp.py", line 52, in load_wsgiapp
    return util.import_app(self.app_uri)
  File "/dh/lib/python3.6/site-packages/gunicorn/util.py", line 352, in import_app
    __import__(module)
  File "/dh/dhru/wsgi.py", line 16, in <module>
    application = get_wsgi_application()
  File "/dh/lib/python3.6/site-packages/django/core/wsgi.py", line 13, in get_wsgi_application
    django.setup(set_prefix=False)
  File "/dh/lib/python3.6/site-packages/django/__init__.py", line 27, in setup
    apps.populate(settings.INSTALLED_APPS)
  File "/dh/lib/python3.6/site-packages/django/apps/registry.py", line 108, in populate
    app_config.import_models()
  File "/dh/lib/python3.6/site-packages/django/apps/config.py", line 202, in import_models
    self.models_module = import_module(models_module_name)
  File "/dh/lib/python3.6/importlib/__init__.py", line 126, in import_module
    return _bootstrap._gcd_import(name[level:], package, level)
  File "/dh/lib/python3.6/site-packages/social_auth/models.py", line 4, in <module>
    from django.utils.importlib import import_module
ModuleNotFoundError: No module named 'django.utils.importlib'
[2017-10-30 11:38:20 +0000] [700] [INFO] Worker exiting (pid: 700)
Traceback (most recent call last):
  File "/dh/lib/python3.6/site-packages/gunicorn/arbiter.py", line 209, in run
    self.sleep()
  File "/dh/lib/python3.6/site-packages/gunicorn/arbiter.py", line 359, in sleep
    ready = select.select([self.PIPE[0]], [], [], 1.0)
  File "/dh/lib/python3.6/site-packages/gunicorn/arbiter.py", line 244, in handle_chld
    self.reap_workers()
  File "/dh/lib/python3.6/site-packages/gunicorn/arbiter.py", line 524, in reap_workers
    raise HaltServer(reason, self.WORKER_BOOT_ERROR)
gunicorn.errors.HaltServer: <HaltServer 'Worker failed to boot.' 3>

During handling of the above exception, another exception occurred:

Traceback (most recent call last):
  File "/dh/bin/gunicorn", line 11, in <module>
    sys.exit(run())
  File "/dh/lib/python3.6/site-packages/gunicorn/app/wsgiapp.py", line 74, in run
    WSGIApplication("%(prog)s [OPTIONS] [APP_MODULE]").run()
  File "/dh/lib/python3.6/site-packages/gunicorn/app/base.py", line 203, in run
    super(Application, self).run()
  File "/dh/lib/python3.6/site-packages/gunicorn/app/base.py", line 72, in run
    Arbiter(self).run()
  File "/dh/lib/python3.6/site-packages/gunicorn/arbiter.py", line 231, in run
    self.halt(reason=inst.reason, exit_status=inst.exit_status)
  File "/dh/lib/python3.6/site-packages/gunicorn/arbiter.py", line 344, in halt
    self.stop()
  File "/dh/lib/python3.6/site-packages/gunicorn/arbiter.py", line 393, in stop
    time.sleep(0.1)
  File "/dh/lib/python3.6/site-packages/gunicorn/arbiter.py", line 244, in handle_chld
    self.reap_workers()
  File "/dh/lib/python3.6/site-packages/gunicorn/arbiter.py", line 524, in reap_workers
    raise HaltServer(reason, self.WORKER_BOOT_ERROR)
gunicorn.errors.HaltServer: <HaltServer 'Worker failed to boot.' 3>
Starting dhru as dhuser
In /dh start venv
Now venv Activate
Start Gunicorn
[2017-10-30 14:38:22 +0300] [702] [INFO] Starting gunicorn 19.7.1
[2017-10-30 14:38:22 +0300] [702] [INFO] Listening at: unix:/dh/run/gunicorn.sock (702)
[2017-10-30 14:38:22 +0300] [702] [INFO] Using worker: sync
[2017-10-30 14:38:22 +0300] [709] [INFO] Booting worker with pid: 709
[2017-10-30 14:38:22 +0300] [710] [INFO] Booting worker with pid: 710
[2017-10-30 14:38:22 +0300] [713] [INFO] Booting worker with pid: 713
[2017-10-30 11:38:22 +0000] [709] [ERROR] Exception in worker process
Traceback (most recent call last):
  File "/dh/lib/python3.6/site-packages/gunicorn/arbiter.py", line 578, in spawn_worker
    worker.init_process()
  File "/dh/lib/python3.6/site-packages/gunicorn/workers/base.py", line 126, in init_process
    self.load_wsgi()
  File "/dh/lib/python3.6/site-packages/gunicorn/workers/base.py", line 135, in load_wsgi
    self.wsgi = self.app.wsgi()
  File "/dh/lib/python3.6/site-packages/gunicorn/app/base.py", line 67, in wsgi
    self.callable = self.load()
  File "/dh/lib/python3.6/site-packages/gunicorn/app/wsgiapp.py", line 65, in load
    return self.load_wsgiapp()
  File "/dh/lib/python3.6/site-packages/gunicorn/app/wsgiapp.py", line 52, in load_wsgiapp
    return util.import_app(self.app_uri)
  File "/dh/lib/python3.6/site-packages/gunicorn/util.py", line 352, in import_app
    __import__(module)
  File "/dh/dhru/wsgi.py", line 16, in <module>
    application = get_wsgi_application()
  File "/dh/lib/python3.6/site-packages/django/core/wsgi.py", line 13, in get_wsgi_application
    django.setup(set_prefix=False)
  File "/dh/lib/python3.6/site-packages/django/__init__.py", line 27, in setup
    apps.populate(settings.INSTALLED_APPS)
  File "/dh/lib/python3.6/site-packages/django/apps/registry.py", line 108, in populate
    app_config.import_models()
  File "/dh/lib/python3.6/site-packages/django/apps/config.py", line 202, in import_models
    self.models_module = import_module(models_module_name)
  File "/dh/lib/python3.6/importlib/__init__.py", line 126, in import_module
    return _bootstrap._gcd_import(name[level:], package, level)
  File "/dh/lib/python3.6/site-packages/social_auth/models.py", line 4, in <module>
    from django.utils.importlib import import_module
ModuleNotFoundError: No module named 'django.utils.importlib'
[2017-10-30 11:38:22 +0000] [709] [INFO] Worker exiting (pid: 709)
[2017-10-30 11:38:22 +0000] [710] [ERROR] Exception in worker process
Traceback (most recent call last):
  File "/dh/lib/python3.6/site-packages/gunicorn/arbiter.py", line 578, in spawn_worker
    worker.init_process()
  File "/dh/lib/python3.6/site-packages/gunicorn/workers/base.py", line 126, in init_process
    self.load_wsgi()
  File "/dh/lib/python3.6/site-packages/gunicorn/workers/base.py", line 135, in load_wsgi
    self.wsgi = self.app.wsgi()
  File "/dh/lib/python3.6/site-packages/gunicorn/app/base.py", line 67, in wsgi
    self.callable = self.load()
  File "/dh/lib/python3.6/site-packages/gunicorn/app/wsgiapp.py", line 65, in load
    return self.load_wsgiapp()
  File "/dh/lib/python3.6/site-packages/gunicorn/app/wsgiapp.py", line 52, in load_wsgiapp
    return util.import_app(self.app_uri)
  File "/dh/lib/python3.6/site-packages/gunicorn/util.py", line 352, in import_app
    __import__(module)
  File "/dh/dhru/wsgi.py", line 16, in <module>
    application = get_wsgi_application()
  File "/dh/lib/python3.6/site-packages/django/core/wsgi.py", line 13, in get_wsgi_application
    django.setup(set_prefix=False)
  File "/dh/lib/python3.6/site-packages/django/__init__.py", line 27, in setup
    apps.populate(settings.INSTALLED_APPS)
  File "/dh/lib/python3.6/site-packages/django/apps/registry.py", line 108, in populate
    app_config.import_models()
  File "/dh/lib/python3.6/site-packages/django/apps/config.py", line 202, in import_models
    self.models_module = import_module(models_module_name)
  File "/dh/lib/python3.6/importlib/__init__.py", line 126, in import_module
    return _bootstrap._gcd_import(name[level:], package, level)
  File "/dh/lib/python3.6/site-packages/social_auth/models.py", line 4, in <module>
    from django.utils.importlib import import_module
ModuleNotFoundError: No module named 'django.utils.importlib'
[2017-10-30 11:38:22 +0000] [710] [INFO] Worker exiting (pid: 710)
Traceback (most recent call last):
  File "/dh/lib/python3.6/site-packages/gunicorn/arbiter.py", line 209, in run
    self.sleep()
  File "/dh/lib/python3.6/site-packages/gunicorn/arbiter.py", line 359, in sleep
    ready = select.select([self.PIPE[0]], [], [], 1.0)
  File "/dh/lib/python3.6/site-packages/gunicorn/arbiter.py", line 244, in handle_chld
    self.reap_workers()
  File "/dh/lib/python3.6/site-packages/gunicorn/arbiter.py", line 524, in reap_workers
    raise HaltServer(reason, self.WORKER_BOOT_ERROR)
gunicorn.errors.HaltServer: <HaltServer 'Worker failed to boot.' 3>

During handling of the above exception, another exception occurred:

Traceback (most recent call last):
  File "/dh/bin/gunicorn", line 11, in <module>
    sys.exit(run())
  File "/dh/lib/python3.6/site-packages/gunicorn/app/wsgiapp.py", line 74, in run
    WSGIApplication("%(prog)s [OPTIONS] [APP_MODULE]").run()
  File "/dh/lib/python3.6/site-packages/gunicorn/app/base.py", line 203, in run
    super(Application, self).run()
  File "/dh/lib/python3.6/site-packages/gunicorn/app/base.py", line 72, in run
    Arbiter(self).run()
  File "/dh/lib/python3.6/site-packages/gunicorn/arbiter.py", line 231, in run
    self.halt(reason=inst.reason, exit_status=inst.exit_status)
  File "/dh/lib/python3.6/site-packages/gunicorn/arbiter.py", line 344, in halt
    self.stop()
  File "/dh/lib/python3.6/site-packages/gunicorn/arbiter.py", line 393, in stop
    time.sleep(0.1)
  File "/dh/lib/python3.6/site-packages/gunicorn/arbiter.py", line 244, in handle_chld
    self.reap_workers()
  File "/dh/lib/python3.6/site-packages/gunicorn/arbiter.py", line 524, in reap_workers
    raise HaltServer(reason, self.WORKER_BOOT_ERROR)
gunicorn.errors.HaltServer: <HaltServer 'Worker failed to boot.' 3>
Starting dhru as dhuser
In /dh start venv
Now venv Activate
Start Gunicorn
[2017-10-30 14:38:24 +0300] [715] [INFO] Starting gunicorn 19.7.1
[2017-10-30 14:38:24 +0300] [715] [INFO] Listening at: unix:/dh/run/gunicorn.sock (715)
[2017-10-30 14:38:24 +0300] [715] [INFO] Using worker: sync
[2017-10-30 14:38:24 +0300] [722] [INFO] Booting worker with pid: 722
[2017-10-30 14:38:24 +0300] [723] [INFO] Booting worker with pid: 723
[2017-10-30 14:38:24 +0300] [724] [INFO] Booting worker with pid: 724
[2017-10-30 11:38:25 +0000] [722] [ERROR] Exception in worker process
Traceback (most recent call last):
  File "/dh/lib/python3.6/site-packages/gunicorn/arbiter.py", line 578, in spawn_worker
    worker.init_process()
  File "/dh/lib/python3.6/site-packages/gunicorn/workers/base.py", line 126, in init_process
    self.load_wsgi()
  File "/dh/lib/python3.6/site-packages/gunicorn/workers/base.py", line 135, in load_wsgi
    self.wsgi = self.app.wsgi()
  File "/dh/lib/python3.6/site-packages/gunicorn/app/base.py", line 67, in wsgi
    self.callable = self.load()
  File "/dh/lib/python3.6/site-packages/gunicorn/app/wsgiapp.py", line 65, in load
    return self.load_wsgiapp()
  File "/dh/lib/python3.6/site-packages/gunicorn/app/wsgiapp.py", line 52, in load_wsgiapp
    return util.import_app(self.app_uri)
  File "/dh/lib/python3.6/site-packages/gunicorn/util.py", line 352, in import_app
    __import__(module)
  File "/dh/dhru/wsgi.py", line 16, in <module>
    application = get_wsgi_application()
  File "/dh/lib/python3.6/site-packages/django/core/wsgi.py", line 13, in get_wsgi_application
    django.setup(set_prefix=False)
  File "/dh/lib/python3.6/site-packages/django/__init__.py", line 27, in setup
    apps.populate(settings.INSTALLED_APPS)
  File "/dh/lib/python3.6/site-packages/django/apps/registry.py", line 108, in populate
    app_config.import_models()
  File "/dh/lib/python3.6/site-packages/django/apps/config.py", line 202, in import_models
    self.models_module = import_module(models_module_name)
  File "/dh/lib/python3.6/importlib/__init__.py", line 126, in import_module
    return _bootstrap._gcd_import(name[level:], package, level)
  File "/dh/lib/python3.6/site-packages/social_auth/models.py", line 4, in <module>
    from django.utils.importlib import import_module
ModuleNotFoundError: No module named 'django.utils.importlib'
[2017-10-30 11:38:25 +0000] [722] [INFO] Worker exiting (pid: 722)
[2017-10-30 11:38:25 +0000] [723] [ERROR] Exception in worker process
Traceback (most recent call last):
  File "/dh/lib/python3.6/site-packages/gunicorn/arbiter.py", line 578, in spawn_worker
    worker.init_process()
  File "/dh/lib/python3.6/site-packages/gunicorn/workers/base.py", line 126, in init_process
    self.load_wsgi()
  File "/dh/lib/python3.6/site-packages/gunicorn/workers/base.py", line 135, in load_wsgi
    self.wsgi = self.app.wsgi()
  File "/dh/lib/python3.6/site-packages/gunicorn/app/base.py", line 67, in wsgi
    self.callable = self.load()
  File "/dh/lib/python3.6/site-packages/gunicorn/app/wsgiapp.py", line 65, in load
    return self.load_wsgiapp()
  File "/dh/lib/python3.6/site-packages/gunicorn/app/wsgiapp.py", line 52, in load_wsgiapp
    return util.import_app(self.app_uri)
  File "/dh/lib/python3.6/site-packages/gunicorn/util.py", line 352, in import_app
    __import__(module)
  File "/dh/dhru/wsgi.py", line 16, in <module>
    application = get_wsgi_application()
  File "/dh/lib/python3.6/site-packages/django/core/wsgi.py", line 13, in get_wsgi_application
    django.setup(set_prefix=False)
  File "/dh/lib/python3.6/site-packages/django/__init__.py", line 27, in setup
    apps.populate(settings.INSTALLED_APPS)
  File "/dh/lib/python3.6/site-packages/django/apps/registry.py", line 108, in populate
    app_config.import_models()
  File "/dh/lib/python3.6/site-packages/django/apps/config.py", line 202, in import_models
    self.models_module = import_module(models_module_name)
  File "/dh/lib/python3.6/importlib/__init__.py", line 126, in import_module
    return _bootstrap._gcd_import(name[level:], package, level)
  File "/dh/lib/python3.6/site-packages/social_auth/models.py", line 4, in <module>
    from django.utils.importlib import import_module
ModuleNotFoundError: No module named 'django.utils.importlib'
[2017-10-30 11:38:25 +0000] [723] [INFO] Worker exiting (pid: 723)
[2017-10-30 11:38:25 +0000] [724] [ERROR] Exception in worker process
Traceback (most recent call last):
  File "/dh/lib/python3.6/site-packages/gunicorn/arbiter.py", line 578, in spawn_worker
    worker.init_process()
  File "/dh/lib/python3.6/site-packages/gunicorn/workers/base.py", line 126, in init_process
    self.load_wsgi()
  File "/dh/lib/python3.6/site-packages/gunicorn/workers/base.py", line 135, in load_wsgi
    self.wsgi = self.app.wsgi()
  File "/dh/lib/python3.6/site-packages/gunicorn/app/base.py", line 67, in wsgi
    self.callable = self.load()
  File "/dh/lib/python3.6/site-packages/gunicorn/app/wsgiapp.py", line 65, in load
    return self.load_wsgiapp()
  File "/dh/lib/python3.6/site-packages/gunicorn/app/wsgiapp.py", line 52, in load_wsgiapp
    return util.import_app(self.app_uri)
  File "/dh/lib/python3.6/site-packages/gunicorn/util.py", line 352, in import_app
    __import__(module)
  File "/dh/dhru/wsgi.py", line 16, in <module>
    application = get_wsgi_application()
  File "/dh/lib/python3.6/site-packages/django/core/wsgi.py", line 13, in get_wsgi_application
    django.setup(set_prefix=False)
  File "/dh/lib/python3.6/site-packages/django/__init__.py", line 27, in setup
    apps.populate(settings.INSTALLED_APPS)
  File "/dh/lib/python3.6/site-packages/django/apps/registry.py", line 108, in populate
    app_config.import_models()
  File "/dh/lib/python3.6/site-packages/django/apps/config.py", line 202, in import_models
    self.models_module = import_module(models_module_name)
  File "/dh/lib/python3.6/importlib/__init__.py", line 126, in import_module
    return _bootstrap._gcd_import(name[level:], package, level)
  File "/dh/lib/python3.6/site-packages/social_auth/models.py", line 4, in <module>
    from django.utils.importlib import import_module
ModuleNotFoundError: No module named 'django.utils.importlib'
[2017-10-30 11:38:25 +0000] [724] [INFO] Worker exiting (pid: 724)
[2017-10-30 14:38:25 +0300] [715] [INFO] Shutting down: Master
[2017-10-30 14:38:25 +0300] [715] [INFO] Reason: Worker failed to boot.
Starting dhru as dhuser
In /dh start venv
Now venv Activate
Start Gunicorn
[2017-10-30 14:38:28 +0300] [728] [INFO] Starting gunicorn 19.7.1
[2017-10-30 14:38:28 +0300] [728] [INFO] Listening at: unix:/dh/run/gunicorn.sock (728)
[2017-10-30 14:38:28 +0300] [728] [INFO] Using worker: sync
[2017-10-30 14:38:28 +0300] [735] [INFO] Booting worker with pid: 735
[2017-10-30 14:38:28 +0300] [736] [INFO] Booting worker with pid: 736
[2017-10-30 14:38:28 +0300] [737] [INFO] Booting worker with pid: 737
[2017-10-30 11:38:28 +0000] [735] [ERROR] Exception in worker process
Traceback (most recent call last):
  File "/dh/lib/python3.6/site-packages/gunicorn/arbiter.py", line 578, in spawn_worker
    worker.init_process()
  File "/dh/lib/python3.6/site-packages/gunicorn/workers/base.py", line 126, in init_process
    self.load_wsgi()
  File "/dh/lib/python3.6/site-packages/gunicorn/workers/base.py", line 135, in load_wsgi
    self.wsgi = self.app.wsgi()
  File "/dh/lib/python3.6/site-packages/gunicorn/app/base.py", line 67, in wsgi
    self.callable = self.load()
  File "/dh/lib/python3.6/site-packages/gunicorn/app/wsgiapp.py", line 65, in load
    return self.load_wsgiapp()
  File "/dh/lib/python3.6/site-packages/gunicorn/app/wsgiapp.py", line 52, in load_wsgiapp
    return util.import_app(self.app_uri)
  File "/dh/lib/python3.6/site-packages/gunicorn/util.py", line 352, in import_app
    __import__(module)
  File "/dh/dhru/wsgi.py", line 16, in <module>
    application = get_wsgi_application()
  File "/dh/lib/python3.6/site-packages/django/core/wsgi.py", line 13, in get_wsgi_application
    django.setup(set_prefix=False)
  File "/dh/lib/python3.6/site-packages/django/__init__.py", line 27, in setup
    apps.populate(settings.INSTALLED_APPS)
  File "/dh/lib/python3.6/site-packages/django/apps/registry.py", line 108, in populate
    app_config.import_models()
  File "/dh/lib/python3.6/site-packages/django/apps/config.py", line 202, in import_models
    self.models_module = import_module(models_module_name)
  File "/dh/lib/python3.6/importlib/__init__.py", line 126, in import_module
    return _bootstrap._gcd_import(name[level:], package, level)
  File "/dh/lib/python3.6/site-packages/social_auth/models.py", line 4, in <module>
    from django.utils.importlib import import_module
ModuleNotFoundError: No module named 'django.utils.importlib'
[2017-10-30 11:38:28 +0000] [735] [INFO] Worker exiting (pid: 735)
[2017-10-30 11:38:28 +0000] [736] [ERROR] Exception in worker process
Traceback (most recent call last):
  File "/dh/lib/python3.6/site-packages/gunicorn/arbiter.py", line 578, in spawn_worker
    worker.init_process()
  File "/dh/lib/python3.6/site-packages/gunicorn/workers/base.py", line 126, in init_process
    self.load_wsgi()
  File "/dh/lib/python3.6/site-packages/gunicorn/workers/base.py", line 135, in load_wsgi
    self.wsgi = self.app.wsgi()
  File "/dh/lib/python3.6/site-packages/gunicorn/app/base.py", line 67, in wsgi
    self.callable = self.load()
  File "/dh/lib/python3.6/site-packages/gunicorn/app/wsgiapp.py", line 65, in load
    return self.load_wsgiapp()
  File "/dh/lib/python3.6/site-packages/gunicorn/app/wsgiapp.py", line 52, in load_wsgiapp
    return util.import_app(self.app_uri)
  File "/dh/lib/python3.6/site-packages/gunicorn/util.py", line 352, in import_app
    __import__(module)
  File "/dh/dhru/wsgi.py", line 16, in <module>
    application = get_wsgi_application()
  File "/dh/lib/python3.6/site-packages/django/core/wsgi.py", line 13, in get_wsgi_application
    django.setup(set_prefix=False)
  File "/dh/lib/python3.6/site-packages/django/__init__.py", line 27, in setup
    apps.populate(settings.INSTALLED_APPS)
  File "/dh/lib/python3.6/site-packages/django/apps/registry.py", line 108, in populate
    app_config.import_models()
  File "/dh/lib/python3.6/site-packages/django/apps/config.py", line 202, in import_models
    self.models_module = import_module(models_module_name)
  File "/dh/lib/python3.6/importlib/__init__.py", line 126, in import_module
    return _bootstrap._gcd_import(name[level:], package, level)
  File "/dh/lib/python3.6/site-packages/social_auth/models.py", line 4, in <module>
    from django.utils.importlib import import_module
ModuleNotFoundError: No module named 'django.utils.importlib'
[2017-10-30 11:38:28 +0000] [736] [INFO] Worker exiting (pid: 736)
[2017-10-30 11:38:28 +0000] [737] [ERROR] Exception in worker process
Traceback (most recent call last):
  File "/dh/lib/python3.6/site-packages/gunicorn/arbiter.py", line 578, in spawn_worker
    worker.init_process()
  File "/dh/lib/python3.6/site-packages/gunicorn/workers/base.py", line 126, in init_process
    self.load_wsgi()
  File "/dh/lib/python3.6/site-packages/gunicorn/workers/base.py", line 135, in load_wsgi
    self.wsgi = self.app.wsgi()
  File "/dh/lib/python3.6/site-packages/gunicorn/app/base.py", line 67, in wsgi
    self.callable = self.load()
  File "/dh/lib/python3.6/site-packages/gunicorn/app/wsgiapp.py", line 65, in load
    return self.load_wsgiapp()
  File "/dh/lib/python3.6/site-packages/gunicorn/app/wsgiapp.py", line 52, in load_wsgiapp
    return util.import_app(self.app_uri)
  File "/dh/lib/python3.6/site-packages/gunicorn/util.py", line 352, in import_app
    __import__(module)
  File "/dh/dhru/wsgi.py", line 16, in <module>
    application = get_wsgi_application()
  File "/dh/lib/python3.6/site-packages/django/core/wsgi.py", line 13, in get_wsgi_application
    django.setup(set_prefix=False)
  File "/dh/lib/python3.6/site-packages/django/__init__.py", line 27, in setup
    apps.populate(settings.INSTALLED_APPS)
  File "/dh/lib/python3.6/site-packages/django/apps/registry.py", line 108, in populate
    app_config.import_models()
  File "/dh/lib/python3.6/site-packages/django/apps/config.py", line 202, in import_models
    self.models_module = import_module(models_module_name)
  File "/dh/lib/python3.6/importlib/__init__.py", line 126, in import_module
    return _bootstrap._gcd_import(name[level:], package, level)
  File "/dh/lib/python3.6/site-packages/social_auth/models.py", line 4, in <module>
    from django.utils.importlib import import_module
ModuleNotFoundError: No module named 'django.utils.importlib'
[2017-10-30 11:38:28 +0000] [737] [INFO] Worker exiting (pid: 737)
Traceback (most recent call last):
  File "/dh/lib/python3.6/site-packages/gunicorn/arbiter.py", line 209, in run
    self.sleep()
  File "/dh/lib/python3.6/site-packages/gunicorn/arbiter.py", line 359, in sleep
    ready = select.select([self.PIPE[0]], [], [], 1.0)
  File "/dh/lib/python3.6/site-packages/gunicorn/arbiter.py", line 244, in handle_chld
    self.reap_workers()
  File "/dh/lib/python3.6/site-packages/gunicorn/arbiter.py", line 524, in reap_workers
    raise HaltServer(reason, self.WORKER_BOOT_ERROR)
gunicorn.errors.HaltServer: <HaltServer 'Worker failed to boot.' 3>

During handling of the above exception, another exception occurred:

Traceback (most recent call last):
  File "/dh/bin/gunicorn", line 11, in <module>
    sys.exit(run())
  File "/dh/lib/python3.6/site-packages/gunicorn/app/wsgiapp.py", line 74, in run
    WSGIApplication("%(prog)s [OPTIONS] [APP_MODULE]").run()
  File "/dh/lib/python3.6/site-packages/gunicorn/app/base.py", line 203, in run
    super(Application, self).run()
  File "/dh/lib/python3.6/site-packages/gunicorn/app/base.py", line 72, in run
    Arbiter(self).run()
  File "/dh/lib/python3.6/site-packages/gunicorn/arbiter.py", line 231, in run
    self.halt(reason=inst.reason, exit_status=inst.exit_status)
  File "/dh/lib/python3.6/site-packages/gunicorn/arbiter.py", line 344, in halt
    self.stop()
  File "/dh/lib/python3.6/site-packages/gunicorn/arbiter.py", line 393, in stop
    time.sleep(0.1)
  File "/dh/lib/python3.6/site-packages/gunicorn/arbiter.py", line 244, in handle_chld
    self.reap_workers()
  File "/dh/lib/python3.6/site-packages/gunicorn/arbiter.py", line 524, in reap_workers
    raise HaltServer(reason, self.WORKER_BOOT_ERROR)
gunicorn.errors.HaltServer: <HaltServer 'Worker failed to boot.' 3>
